2018-12-19 08:59:36,152 [Dummy-1:3916] [django.db.backends:111] [utils:execute] [DEBUG]- (0.003) 
            SELECT name, type FROM sqlite_master
            WHERE type in ('table', 'view') AND NOT name='sqlite_sequence'
            ORDER BY name; args=None
2018-12-19 09:03:22,467 [Thread-2:48672] [my_blog.views:11] [views:index] [ERROR]- [Errno 2] No such file or directory: './test'
2018-12-19 09:03:22,484 [Thread-2:48672] [django.server:136] [basehttp:log_message] [INFO]- "GET / HTTP/1.1" 200 14977
2018-12-19 09:03:22,643 [Thread-2:48672] [django.server:136] [basehttp:log_message] [INFO]- "GET /static/css/base.css HTTP/1.1" 200 8732
2018-12-19 09:03:22,645 [Thread-3:47372] [django.server:136] [basehttp:log_message] [INFO]- "GET /static/css/index.css HTTP/1.1" 200 4946
2018-12-19 09:03:22,646 [Thread-5:47192] [django.server:136] [basehttp:log_message] [INFO]- "GET /static/js/sliders.js HTTP/1.1" 200 4505
2018-12-19 09:03:22,646 [Thread-6:47824] [django.server:136] [basehttp:log_message] [INFO]- "GET /static/js/nav.js HTTP/1.1" 200 238
2018-12-19 09:03:22,648 [Thread-4:10124] [django.server:136] [basehttp:log_message] [INFO]- "GET /static/js/jquery.min.js HTTP/1.1" 200 95790
2018-12-19 09:03:22,657 [Thread-4:10124] [django.template:872] [base:_resolve_lookup] [DEBUG]- Exception while resolving variable 'name' in template 'unknown'.
Traceback (most recent call last):
  File "D:\python_env\blog\lib\site-packages\django\core\handlers\exception.py", line 34, in inner
    response = get_response(request)
  File "D:\python_env\blog\lib\site-packages\django\core\handlers\base.py", line 111, in _get_response
    resolver_match = resolver.resolve(request.path_info)
  File "D:\python_env\blog\lib\site-packages\django\urls\resolvers.py", line 520, in resolve
    raise Resolver404({'tried': tried, 'path': new_path})
django.urls.exceptions.Resolver404: {'tried': [[<URLResolver <URLPattern list> (admin:admin) 'admin/'>], [<URLPattern '^$' [name='index']>]], 'path': 'images/a1.jpg'}

During handling of the above exception, another exception occurred:

Traceback (most recent call last):
  File "D:\python_env\blog\lib\site-packages\django\template\base.py", line 829, in _resolve_lookup
    current = current[bit]
TypeError: 'URLResolver' object is not subscriptable

During handling of the above exception, another exception occurred:

Traceback (most recent call last):
  File "D:\python_env\blog\lib\site-packages\django\template\base.py", line 837, in _resolve_lookup
    current = getattr(current, bit)
AttributeError: 'URLResolver' object has no attribute 'name'

During handling of the above exception, another exception occurred:

Traceback (most recent call last):
  File "D:\python_env\blog\lib\site-packages\django\template\base.py", line 843, in _resolve_lookup
    current = current[int(bit)]
ValueError: invalid literal for int() with base 10: 'name'

During handling of the above exception, another exception occurred:

Traceback (most recent call last):
  File "D:\python_env\blog\lib\site-packages\django\template\base.py", line 850, in _resolve_lookup
    (bit, current))  # missing attribute
django.template.base.VariableDoesNotExist: Failed lookup for key [name] in <URLResolver <URLPattern list> (admin:admin) 'admin/'>
2018-12-19 09:03:22,662 [Thread-4:10124] [django.server:136] [basehttp:log_message] [WARNING]- "GET /images/a1.jpg HTTP/1.1" 404 2092
2018-12-19 09:03:22,670 [Thread-4:10124] [django.template:872] [base:_resolve_lookup] [DEBUG]- Exception while resolving variable 'name' in template 'unknown'.
Traceback (most recent call last):
  File "D:\python_env\blog\lib\site-packages\django\core\handlers\exception.py", line 34, in inner
    response = get_response(request)
  File "D:\python_env\blog\lib\site-packages\django\core\handlers\base.py", line 111, in _get_response
    resolver_match = resolver.resolve(request.path_info)
  File "D:\python_env\blog\lib\site-packages\django\urls\resolvers.py", line 520, in resolve
    raise Resolver404({'tried': tried, 'path': new_path})
django.urls.exceptions.Resolver404: {'tried': [[<URLResolver <URLPattern list> (admin:admin) 'admin/'>], [<URLPattern '^$' [name='index']>]], 'path': 'images/a2.jpg'}

During handling of the above exception, another exception occurred:

Traceback (most recent call last):
  File "D:\python_env\blog\lib\site-packages\django\template\base.py", line 829, in _resolve_lookup
    current = current[bit]
TypeError: 'URLResolver' object is not subscriptable

During handling of the above exception, another exception occurred:

Traceback (most recent call last):
  File "D:\python_env\blog\lib\site-packages\django\template\base.py", line 837, in _resolve_lookup
    current = getattr(current, bit)
AttributeError: 'URLResolver' object has no attribute 'name'

During handling of the above exception, another exception occurred:

Traceback (most recent call last):
  File "D:\python_env\blog\lib\site-packages\django\template\base.py", line 843, in _resolve_lookup
    current = current[int(bit)]
ValueError: invalid literal for int() with base 10: 'name'

During handling of the above exception, another exception occurred:

Traceback (most recent call last):
  File "D:\python_env\blog\lib\site-packages\django\template\base.py", line 850, in _resolve_lookup
    (bit, current))  # missing attribute
django.template.base.VariableDoesNotExist: Failed lookup for key [name] in <URLResolver <URLPattern list> (admin:admin) 'admin/'>
2018-12-19 09:03:22,672 [Thread-4:10124] [django.server:136] [basehttp:log_message] [WARNING]- "GET /images/a2.jpg HTTP/1.1" 404 2092
2018-12-19 09:03:22,678 [Thread-4:10124] [django.template:872] [base:_resolve_lookup] [DEBUG]- Exception while resolving variable 'name' in template 'unknown'.
Traceback (most recent call last):
  File "D:\python_env\blog\lib\site-packages\django\core\handlers\exception.py", line 34, in inner
    response = get_response(request)
  File "D:\python_env\blog\lib\site-packages\django\core\handlers\base.py", line 111, in _get_response
    resolver_match = resolver.resolve(request.path_info)
  File "D:\python_env\blog\lib\site-packages\django\urls\resolvers.py", line 520, in resolve
    raise Resolver404({'tried': tried, 'path': new_path})
django.urls.exceptions.Resolver404: {'tried': [[<URLResolver <URLPattern list> (admin:admin) 'admin/'>], [<URLPattern '^$' [name='index']>]], 'path': 'images/a3.jpg'}

During handling of the above exception, another exception occurred:

Traceback (most recent call last):
  File "D:\python_env\blog\lib\site-packages\django\template\base.py", line 829, in _resolve_lookup
    current = current[bit]
TypeError: 'URLResolver' object is not subscriptable

During handling of the above exception, another exception occurred:

Traceback (most recent call last):
  File "D:\python_env\blog\lib\site-packages\django\template\base.py", line 837, in _resolve_lookup
    current = getattr(current, bit)
AttributeError: 'URLResolver' object has no attribute 'name'

During handling of the above exception, another exception occurred:

Traceback (most recent call last):
  File "D:\python_env\blog\lib\site-packages\django\template\base.py", line 843, in _resolve_lookup
    current = current[int(bit)]
ValueError: invalid literal for int() with base 10: 'name'

During handling of the above exception, another exception occurred:

Traceback (most recent call last):
  File "D:\python_env\blog\lib\site-packages\django\template\base.py", line 850, in _resolve_lookup
    (bit, current))  # missing attribute
django.template.base.VariableDoesNotExist: Failed lookup for key [name] in <URLResolver <URLPattern list> (admin:admin) 'admin/'>
2018-12-19 09:03:22,680 [Thread-4:10124] [django.server:136] [basehttp:log_message] [WARNING]- "GET /images/a3.jpg HTTP/1.1" 404 2092
2018-12-19 09:03:22,687 [Thread-4:10124] [django.template:872] [base:_resolve_lookup] [DEBUG]- Exception while resolving variable 'name' in template 'unknown'.
Traceback (most recent call last):
  File "D:\python_env\blog\lib\site-packages\django\core\handlers\exception.py", line 34, in inner
    response = get_response(request)
  File "D:\python_env\blog\lib\site-packages\django\core\handlers\base.py", line 111, in _get_response
    resolver_match = resolver.resolve(request.path_info)
  File "D:\python_env\blog\lib\site-packages\django\urls\resolvers.py", line 520, in resolve
    raise Resolver404({'tried': tried, 'path': new_path})
django.urls.exceptions.Resolver404: {'tried': [[<URLResolver <URLPattern list> (admin:admin) 'admin/'>], [<URLPattern '^$' [name='index']>]], 'path': 'images/a4.jpg'}

During handling of the above exception, another exception occurred:

Traceback (most recent call last):
  File "D:\python_env\blog\lib\site-packages\django\template\base.py", line 829, in _resolve_lookup
    current = current[bit]
TypeError: 'URLResolver' object is not subscriptable

During handling of the above exception, another exception occurred:

Traceback (most recent call last):
  File "D:\python_env\blog\lib\site-packages\django\template\base.py", line 837, in _resolve_lookup
    current = getattr(current, bit)
AttributeError: 'URLResolver' object has no attribute 'name'

During handling of the above exception, another exception occurred:

Traceback (most recent call last):
  File "D:\python_env\blog\lib\site-packages\django\template\base.py", line 843, in _resolve_lookup
    current = current[int(bit)]
ValueError: invalid literal for int() with base 10: 'name'

During handling of the above exception, another exception occurred:

Traceback (most recent call last):
  File "D:\python_env\blog\lib\site-packages\django\template\base.py", line 850, in _resolve_lookup
    (bit, current))  # missing attribute
django.template.base.VariableDoesNotExist: Failed lookup for key [name] in <URLResolver <URLPattern list> (admin:admin) 'admin/'>
2018-12-19 09:03:22,689 [Thread-4:10124] [django.server:136] [basehttp:log_message] [WARNING]- "GET /images/a4.jpg HTTP/1.1" 404 2092
2018-12-19 09:03:22,789 [Thread-4:10124] [django.server:136] [basehttp:log_message] [INFO]- "GET /static/images/slide-bg.png HTTP/1.1" 200 2792
2018-12-19 09:03:22,867 [Thread-4:10124] [django.server:136] [basehttp:log_message] [INFO]- "GET /static/images/icons.png HTTP/1.1" 200 1459
2018-12-19 09:03:22,869 [Thread-6:47824] [django.server:136] [basehttp:log_message] [INFO]- "GET /static/images/ico_05_1.jpg HTTP/1.1" 200 6397
2018-12-19 09:03:22,870 [Thread-5:47192] [django.server:136] [basehttp:log_message] [INFO]- "GET /static/images/ico_06_1.jpg HTTP/1.1" 200 5493
2018-12-19 09:03:22,871 [Thread-3:47372] [django.server:136] [basehttp:log_message] [INFO]- "GET /static/images/ico_04_1.jpg HTTP/1.1" 200 5451
2018-12-19 09:03:22,871 [Thread-2:48672] [django.server:136] [basehttp:log_message] [INFO]- "GET /static/images/ico_07_1.jpg HTTP/1.1" 200 5618
2018-12-19 09:03:22,873 [Thread-7:39776] [django.server:136] [basehttp:log_message] [INFO]- "GET /static/images/ph2.png HTTP/1.1" 200 1591
2018-12-19 09:03:22,875 [Thread-6:47824] [django.server:136] [basehttp:log_message] [INFO]- "GET /static/images/datepng.png HTTP/1.1" 200 1204
2018-12-19 09:03:22,880 [Thread-2:48672] [django.server:136] [basehttp:log_message] [INFO]- "GET /static/images/newsbg01.png HTTP/1.1" 200 1243
2018-12-19 09:03:22,884 [Thread-6:47824] [django.server:136] [basehttp:log_message] [INFO]- "GET /static/images/newsbg02.png HTTP/1.1" 200 1418
2018-12-19 09:03:22,884 [Thread-7:39776] [django.server:136] [basehttp:log_message] [INFO]- "GET /static/images/newsbg04.png HTTP/1.1" 200 1298
2018-12-19 09:03:22,896 [Thread-2:48672] [django.server:136] [basehttp:log_message] [INFO]- "GET /static/images/newsbg03.png HTTP/1.1" 200 1254
2018-12-19 09:03:23,005 [Thread-2:48672] [django.server:136] [basehttp:log_message] [INFO]- "GET /static/images/silde-nav.png HTTP/1.1" 200 1250
2018-12-19 09:03:23,062 [Thread-2:48672] [django.template:872] [base:_resolve_lookup] [DEBUG]- Exception while resolving variable 'name' in template 'unknown'.
Traceback (most recent call last):
  File "D:\python_env\blog\lib\site-packages\django\core\handlers\exception.py", line 34, in inner
    response = get_response(request)
  File "D:\python_env\blog\lib\site-packages\django\core\handlers\base.py", line 111, in _get_response
    resolver_match = resolver.resolve(request.path_info)
  File "D:\python_env\blog\lib\site-packages\django\urls\resolvers.py", line 520, in resolve
    raise Resolver404({'tried': tried, 'path': new_path})
django.urls.exceptions.Resolver404: {'tried': [[<URLResolver <URLPattern list> (admin:admin) 'admin/'>], [<URLPattern '^$' [name='index']>]], 'path': 'favicon.ico'}

During handling of the above exception, another exception occurred:

Traceback (most recent call last):
  File "D:\python_env\blog\lib\site-packages\django\template\base.py", line 829, in _resolve_lookup
    current = current[bit]
TypeError: 'URLResolver' object is not subscriptable

During handling of the above exception, another exception occurred:

Traceback (most recent call last):
  File "D:\python_env\blog\lib\site-packages\django\template\base.py", line 837, in _resolve_lookup
    current = getattr(current, bit)
AttributeError: 'URLResolver' object has no attribute 'name'

During handling of the above exception, another exception occurred:

Traceback (most recent call last):
  File "D:\python_env\blog\lib\site-packages\django\template\base.py", line 843, in _resolve_lookup
    current = current[int(bit)]
ValueError: invalid literal for int() with base 10: 'name'

During handling of the above exception, another exception occurred:

Traceback (most recent call last):
  File "D:\python_env\blog\lib\site-packages\django\template\base.py", line 850, in _resolve_lookup
    (bit, current))  # missing attribute
django.template.base.VariableDoesNotExist: Failed lookup for key [name] in <URLResolver <URLPattern list> (admin:admin) 'admin/'>
2018-12-19 09:03:23,068 [Thread-2:48672] [django.server:136] [basehttp:log_message] [WARNING]- "GET /favicon.ico HTTP/1.1" 404 2086
2018-12-19 09:07:46,341 [Thread-2:48672] [django.server:136] [basehttp:log_message] [INFO]- "GET /static/images/ico_05.png HTTP/1.1" 200 2404
2018-12-19 09:07:46,382 [Thread-2:48672] [django.server:136] [basehttp:log_message] [INFO]- "GET /static/images/ico_06.png HTTP/1.1" 200 2333
2018-12-19 09:07:47,506 [Thread-2:48672] [django.server:136] [basehttp:log_message] [INFO]- "GET /static/images/ico_04.png HTTP/1.1" 200 2177
2018-12-19 09:07:47,853 [Thread-2:48672] [django.server:136] [basehttp:log_message] [INFO]- "GET /static/images/ico_07.png HTTP/1.1" 200 2692
2018-12-19 09:08:33,407 [Dummy-1:35088] [django.db.backends:111] [utils:execute] [DEBUG]- (0.000) 
            SELECT name, type FROM sqlite_master
            WHERE type in ('table', 'view') AND NOT name='sqlite_sequence'
            ORDER BY name; args=None
2018-12-19 09:09:03,250 [Dummy-1:21056] [django.db.backends:111] [utils:execute] [DEBUG]- (0.000) 
            SELECT name, type FROM sqlite_master
            WHERE type in ('table', 'view') AND NOT name='sqlite_sequence'
            ORDER BY name; args=None
2018-12-19 09:09:22,767 [Dummy-1:47176] [django.db.backends:111] [utils:execute] [DEBUG]- (0.001) 
            SELECT name, type FROM sqlite_master
            WHERE type in ('table', 'view') AND NOT name='sqlite_sequence'
            ORDER BY name; args=None
2018-12-19 09:09:28,841 [Dummy-1:14316] [django.db.backends:111] [utils:execute] [DEBUG]- (0.001) 
            SELECT name, type FROM sqlite_master
            WHERE type in ('table', 'view') AND NOT name='sqlite_sequence'
            ORDER BY name; args=None
2018-12-19 09:09:36,204 [Dummy-1:34992] [django.db.backends:111] [utils:execute] [DEBUG]- (0.001) 
            SELECT name, type FROM sqlite_master
            WHERE type in ('table', 'view') AND NOT name='sqlite_sequence'
            ORDER BY name; args=None
2018-12-19 09:10:16,972 [Dummy-1:49380] [django.db.backends:111] [utils:execute] [DEBUG]- (0.000) 
            SELECT name, type FROM sqlite_master
            WHERE type in ('table', 'view') AND NOT name='sqlite_sequence'
            ORDER BY name; args=None
2018-12-19 09:10:57,563 [Dummy-1:47904] [django.db.backends:111] [utils:execute] [DEBUG]- (0.001) 
            SELECT name, type FROM sqlite_master
            WHERE type in ('table', 'view') AND NOT name='sqlite_sequence'
            ORDER BY name; args=None
2018-12-19 09:12:16,905 [Dummy-1:28008] [django.db.backends:111] [utils:execute] [DEBUG]- (0.000) 
            SELECT name, type FROM sqlite_master
            WHERE type in ('table', 'view') AND NOT name='sqlite_sequence'
            ORDER BY name; args=None
2018-12-19 09:12:20,693 [Dummy-1:48312] [django.db.backends:111] [utils:execute] [DEBUG]- (0.001) 
            SELECT name, type FROM sqlite_master
            WHERE type in ('table', 'view') AND NOT name='sqlite_sequence'
            ORDER BY name; args=None
2018-12-19 09:12:31,823 [Dummy-1:39216] [django.db.backends:111] [utils:execute] [DEBUG]- (0.001) 
            SELECT name, type FROM sqlite_master
            WHERE type in ('table', 'view') AND NOT name='sqlite_sequence'
            ORDER BY name; args=None
2018-12-19 09:47:32,568 [Dummy-1:36824] [django.db.backends:111] [utils:execute] [DEBUG]- (0.001) 
            SELECT name, type FROM sqlite_master
            WHERE type in ('table', 'view') AND NOT name='sqlite_sequence'
            ORDER BY name; args=None
2018-12-19 09:47:37,117 [Thread-2:43808] [my_blog.views:20] [views:index] [ERROR]- [Errno 2] No such file or directory: './test'
2018-12-19 09:47:37,287 [Thread-2:43808] [django.server:136] [basehttp:log_message] [ERROR]- "GET / HTTP/1.1" 500 98262
2018-12-19 09:50:36,214 [Dummy-1:37444] [django.db.backends:111] [utils:execute] [DEBUG]- (0.000) 
            SELECT name, type FROM sqlite_master
            WHERE type in ('table', 'view') AND NOT name='sqlite_sequence'
            ORDER BY name; args=None
2018-12-19 09:50:44,181 [Thread-2:42680] [my_blog.views:20] [views:index] [ERROR]- [Errno 2] No such file or directory: './test'
2018-12-19 09:50:44,218 [Thread-2:42680] [django.server:136] [basehttp:log_message] [INFO]- "GET / HTTP/1.1" 200 14946
2018-12-19 09:50:44,251 [Thread-2:42680] [django.template:872] [base:_resolve_lookup] [DEBUG]- Exception while resolving variable 'name' in template 'unknown'.
Traceback (most recent call last):
  File "D:\python_env\blog\lib\site-packages\django\core\handlers\exception.py", line 34, in inner
    response = get_response(request)
  File "D:\python_env\blog\lib\site-packages\django\core\handlers\base.py", line 111, in _get_response
    resolver_match = resolver.resolve(request.path_info)
  File "D:\python_env\blog\lib\site-packages\django\urls\resolvers.py", line 520, in resolve
    raise Resolver404({'tried': tried, 'path': new_path})
django.urls.exceptions.Resolver404: {'tried': [[<URLResolver <URLPattern list> (admin:admin) 'admin/'>], [<URLPattern '^$' [name='index']>]], 'path': 'images/a1.jpg'}

During handling of the above exception, another exception occurred:

Traceback (most recent call last):
  File "D:\python_env\blog\lib\site-packages\django\template\base.py", line 829, in _resolve_lookup
    current = current[bit]
TypeError: 'URLResolver' object is not subscriptable

During handling of the above exception, another exception occurred:

Traceback (most recent call last):
  File "D:\python_env\blog\lib\site-packages\django\template\base.py", line 837, in _resolve_lookup
    current = getattr(current, bit)
AttributeError: 'URLResolver' object has no attribute 'name'

During handling of the above exception, another exception occurred:

Traceback (most recent call last):
  File "D:\python_env\blog\lib\site-packages\django\template\base.py", line 843, in _resolve_lookup
    current = current[int(bit)]
ValueError: invalid literal for int() with base 10: 'name'

During handling of the above exception, another exception occurred:

Traceback (most recent call last):
  File "D:\python_env\blog\lib\site-packages\django\template\base.py", line 850, in _resolve_lookup
    (bit, current))  # missing attribute
django.template.base.VariableDoesNotExist: Failed lookup for key [name] in <URLResolver <URLPattern list> (admin:admin) 'admin/'>
2018-12-19 09:50:44,255 [Thread-2:42680] [django.server:136] [basehttp:log_message] [WARNING]- "GET /images/a1.jpg HTTP/1.1" 404 2092
2018-12-19 09:50:44,264 [Thread-2:42680] [django.template:872] [base:_resolve_lookup] [DEBUG]- Exception while resolving variable 'name' in template 'unknown'.
Traceback (most recent call last):
  File "D:\python_env\blog\lib\site-packages\django\core\handlers\exception.py", line 34, in inner
    response = get_response(request)
  File "D:\python_env\blog\lib\site-packages\django\core\handlers\base.py", line 111, in _get_response
    resolver_match = resolver.resolve(request.path_info)
  File "D:\python_env\blog\lib\site-packages\django\urls\resolvers.py", line 520, in resolve
    raise Resolver404({'tried': tried, 'path': new_path})
django.urls.exceptions.Resolver404: {'tried': [[<URLResolver <URLPattern list> (admin:admin) 'admin/'>], [<URLPattern '^$' [name='index']>]], 'path': 'images/a2.jpg'}

During handling of the above exception, another exception occurred:

Traceback (most recent call last):
  File "D:\python_env\blog\lib\site-packages\django\template\base.py", line 829, in _resolve_lookup
    current = current[bit]
TypeError: 'URLResolver' object is not subscriptable

During handling of the above exception, another exception occurred:

Traceback (most recent call last):
  File "D:\python_env\blog\lib\site-packages\django\template\base.py", line 837, in _resolve_lookup
    current = getattr(current, bit)
AttributeError: 'URLResolver' object has no attribute 'name'

During handling of the above exception, another exception occurred:

Traceback (most recent call last):
  File "D:\python_env\blog\lib\site-packages\django\template\base.py", line 843, in _resolve_lookup
    current = current[int(bit)]
ValueError: invalid literal for int() with base 10: 'name'

During handling of the above exception, another exception occurred:

Traceback (most recent call last):
  File "D:\python_env\blog\lib\site-packages\django\template\base.py", line 850, in _resolve_lookup
    (bit, current))  # missing attribute
django.template.base.VariableDoesNotExist: Failed lookup for key [name] in <URLResolver <URLPattern list> (admin:admin) 'admin/'>
2018-12-19 09:50:44,267 [Thread-2:42680] [django.server:136] [basehttp:log_message] [WARNING]- "GET /images/a2.jpg HTTP/1.1" 404 2092
2018-12-19 09:50:44,275 [Thread-2:42680] [django.template:872] [base:_resolve_lookup] [DEBUG]- Exception while resolving variable 'name' in template 'unknown'.
Traceback (most recent call last):
  File "D:\python_env\blog\lib\site-packages\django\core\handlers\exception.py", line 34, in inner
    response = get_response(request)
  File "D:\python_env\blog\lib\site-packages\django\core\handlers\base.py", line 111, in _get_response
    resolver_match = resolver.resolve(request.path_info)
  File "D:\python_env\blog\lib\site-packages\django\urls\resolvers.py", line 520, in resolve
    raise Resolver404({'tried': tried, 'path': new_path})
django.urls.exceptions.Resolver404: {'tried': [[<URLResolver <URLPattern list> (admin:admin) 'admin/'>], [<URLPattern '^$' [name='index']>]], 'path': 'images/a3.jpg'}

During handling of the above exception, another exception occurred:

Traceback (most recent call last):
  File "D:\python_env\blog\lib\site-packages\django\template\base.py", line 829, in _resolve_lookup
    current = current[bit]
TypeError: 'URLResolver' object is not subscriptable

During handling of the above exception, another exception occurred:

Traceback (most recent call last):
  File "D:\python_env\blog\lib\site-packages\django\template\base.py", line 837, in _resolve_lookup
    current = getattr(current, bit)
AttributeError: 'URLResolver' object has no attribute 'name'

During handling of the above exception, another exception occurred:

Traceback (most recent call last):
  File "D:\python_env\blog\lib\site-packages\django\template\base.py", line 843, in _resolve_lookup
    current = current[int(bit)]
ValueError: invalid literal for int() with base 10: 'name'

During handling of the above exception, another exception occurred:

Traceback (most recent call last):
  File "D:\python_env\blog\lib\site-packages\django\template\base.py", line 850, in _resolve_lookup
    (bit, current))  # missing attribute
django.template.base.VariableDoesNotExist: Failed lookup for key [name] in <URLResolver <URLPattern list> (admin:admin) 'admin/'>
2018-12-19 09:50:44,278 [Thread-2:42680] [django.server:136] [basehttp:log_message] [WARNING]- "GET /images/a3.jpg HTTP/1.1" 404 2092
2018-12-19 09:50:44,285 [Thread-2:42680] [django.template:872] [base:_resolve_lookup] [DEBUG]- Exception while resolving variable 'name' in template 'unknown'.
Traceback (most recent call last):
  File "D:\python_env\blog\lib\site-packages\django\core\handlers\exception.py", line 34, in inner
    response = get_response(request)
  File "D:\python_env\blog\lib\site-packages\django\core\handlers\base.py", line 111, in _get_response
    resolver_match = resolver.resolve(request.path_info)
  File "D:\python_env\blog\lib\site-packages\django\urls\resolvers.py", line 520, in resolve
    raise Resolver404({'tried': tried, 'path': new_path})
django.urls.exceptions.Resolver404: {'tried': [[<URLResolver <URLPattern list> (admin:admin) 'admin/'>], [<URLPattern '^$' [name='index']>]], 'path': 'images/a4.jpg'}

During handling of the above exception, another exception occurred:

Traceback (most recent call last):
  File "D:\python_env\blog\lib\site-packages\django\template\base.py", line 829, in _resolve_lookup
    current = current[bit]
TypeError: 'URLResolver' object is not subscriptable

During handling of the above exception, another exception occurred:

Traceback (most recent call last):
  File "D:\python_env\blog\lib\site-packages\django\template\base.py", line 837, in _resolve_lookup
    current = getattr(current, bit)
AttributeError: 'URLResolver' object has no attribute 'name'

During handling of the above exception, another exception occurred:

Traceback (most recent call last):
  File "D:\python_env\blog\lib\site-packages\django\template\base.py", line 843, in _resolve_lookup
    current = current[int(bit)]
ValueError: invalid literal for int() with base 10: 'name'

During handling of the above exception, another exception occurred:

Traceback (most recent call last):
  File "D:\python_env\blog\lib\site-packages\django\template\base.py", line 850, in _resolve_lookup
    (bit, current))  # missing attribute
django.template.base.VariableDoesNotExist: Failed lookup for key [name] in <URLResolver <URLPattern list> (admin:admin) 'admin/'>
2018-12-19 09:50:44,287 [Thread-2:42680] [django.server:136] [basehttp:log_message] [WARNING]- "GET /images/a4.jpg HTTP/1.1" 404 2092
2018-12-19 09:50:59,067 [Thread-2:42680] [my_blog.views:20] [views:index] [ERROR]- [Errno 2] No such file or directory: './test'
2018-12-19 09:50:59,081 [Thread-2:42680] [django.server:136] [basehttp:log_message] [INFO]- "GET / HTTP/1.1" 200 14943
2018-12-19 09:50:59,107 [Thread-2:42680] [django.template:872] [base:_resolve_lookup] [DEBUG]- Exception while resolving variable 'name' in template 'unknown'.
Traceback (most recent call last):
  File "D:\python_env\blog\lib\site-packages\django\core\handlers\exception.py", line 34, in inner
    response = get_response(request)
  File "D:\python_env\blog\lib\site-packages\django\core\handlers\base.py", line 111, in _get_response
    resolver_match = resolver.resolve(request.path_info)
  File "D:\python_env\blog\lib\site-packages\django\urls\resolvers.py", line 520, in resolve
    raise Resolver404({'tried': tried, 'path': new_path})
django.urls.exceptions.Resolver404: {'tried': [[<URLResolver <URLPattern list> (admin:admin) 'admin/'>], [<URLPattern '^$' [name='index']>]], 'path': 'images/a1.jpg'}

During handling of the above exception, another exception occurred:

Traceback (most recent call last):
  File "D:\python_env\blog\lib\site-packages\django\template\base.py", line 829, in _resolve_lookup
    current = current[bit]
TypeError: 'URLResolver' object is not subscriptable

During handling of the above exception, another exception occurred:

Traceback (most recent call last):
  File "D:\python_env\blog\lib\site-packages\django\template\base.py", line 837, in _resolve_lookup
    current = getattr(current, bit)
AttributeError: 'URLResolver' object has no attribute 'name'

During handling of the above exception, another exception occurred:

Traceback (most recent call last):
  File "D:\python_env\blog\lib\site-packages\django\template\base.py", line 843, in _resolve_lookup
    current = current[int(bit)]
ValueError: invalid literal for int() with base 10: 'name'

During handling of the above exception, another exception occurred:

Traceback (most recent call last):
  File "D:\python_env\blog\lib\site-packages\django\template\base.py", line 850, in _resolve_lookup
    (bit, current))  # missing attribute
django.template.base.VariableDoesNotExist: Failed lookup for key [name] in <URLResolver <URLPattern list> (admin:admin) 'admin/'>
2018-12-19 09:50:59,110 [Thread-2:42680] [django.server:136] [basehttp:log_message] [WARNING]- "GET /images/a1.jpg HTTP/1.1" 404 2092
2018-12-19 09:50:59,116 [Thread-2:42680] [django.template:872] [base:_resolve_lookup] [DEBUG]- Exception while resolving variable 'name' in template 'unknown'.
Traceback (most recent call last):
  File "D:\python_env\blog\lib\site-packages\django\core\handlers\exception.py", line 34, in inner
    response = get_response(request)
  File "D:\python_env\blog\lib\site-packages\django\core\handlers\base.py", line 111, in _get_response
    resolver_match = resolver.resolve(request.path_info)
  File "D:\python_env\blog\lib\site-packages\django\urls\resolvers.py", line 520, in resolve
    raise Resolver404({'tried': tried, 'path': new_path})
django.urls.exceptions.Resolver404: {'tried': [[<URLResolver <URLPattern list> (admin:admin) 'admin/'>], [<URLPattern '^$' [name='index']>]], 'path': 'images/a2.jpg'}

During handling of the above exception, another exception occurred:

Traceback (most recent call last):
  File "D:\python_env\blog\lib\site-packages\django\template\base.py", line 829, in _resolve_lookup
    current = current[bit]
TypeError: 'URLResolver' object is not subscriptable

During handling of the above exception, another exception occurred:

Traceback (most recent call last):
  File "D:\python_env\blog\lib\site-packages\django\template\base.py", line 837, in _resolve_lookup
    current = getattr(current, bit)
AttributeError: 'URLResolver' object has no attribute 'name'

During handling of the above exception, another exception occurred:

Traceback (most recent call last):
  File "D:\python_env\blog\lib\site-packages\django\template\base.py", line 843, in _resolve_lookup
    current = current[int(bit)]
ValueError: invalid literal for int() with base 10: 'name'

During handling of the above exception, another exception occurred:

Traceback (most recent call last):
  File "D:\python_env\blog\lib\site-packages\django\template\base.py", line 850, in _resolve_lookup
    (bit, current))  # missing attribute
django.template.base.VariableDoesNotExist: Failed lookup for key [name] in <URLResolver <URLPattern list> (admin:admin) 'admin/'>
2018-12-19 09:50:59,118 [Thread-2:42680] [django.server:136] [basehttp:log_message] [WARNING]- "GET /images/a2.jpg HTTP/1.1" 404 2092
2018-12-19 09:50:59,125 [Thread-2:42680] [django.template:872] [base:_resolve_lookup] [DEBUG]- Exception while resolving variable 'name' in template 'unknown'.
Traceback (most recent call last):
  File "D:\python_env\blog\lib\site-packages\django\core\handlers\exception.py", line 34, in inner
    response = get_response(request)
  File "D:\python_env\blog\lib\site-packages\django\core\handlers\base.py", line 111, in _get_response
    resolver_match = resolver.resolve(request.path_info)
  File "D:\python_env\blog\lib\site-packages\django\urls\resolvers.py", line 520, in resolve
    raise Resolver404({'tried': tried, 'path': new_path})
django.urls.exceptions.Resolver404: {'tried': [[<URLResolver <URLPattern list> (admin:admin) 'admin/'>], [<URLPattern '^$' [name='index']>]], 'path': 'images/a3.jpg'}

During handling of the above exception, another exception occurred:

Traceback (most recent call last):
  File "D:\python_env\blog\lib\site-packages\django\template\base.py", line 829, in _resolve_lookup
    current = current[bit]
TypeError: 'URLResolver' object is not subscriptable

During handling of the above exception, another exception occurred:

Traceback (most recent call last):
  File "D:\python_env\blog\lib\site-packages\django\template\base.py", line 837, in _resolve_lookup
    current = getattr(current, bit)
AttributeError: 'URLResolver' object has no attribute 'name'

During handling of the above exception, another exception occurred:

Traceback (most recent call last):
  File "D:\python_env\blog\lib\site-packages\django\template\base.py", line 843, in _resolve_lookup
    current = current[int(bit)]
ValueError: invalid literal for int() with base 10: 'name'

During handling of the above exception, another exception occurred:

Traceback (most recent call last):
  File "D:\python_env\blog\lib\site-packages\django\template\base.py", line 850, in _resolve_lookup
    (bit, current))  # missing attribute
django.template.base.VariableDoesNotExist: Failed lookup for key [name] in <URLResolver <URLPattern list> (admin:admin) 'admin/'>
2018-12-19 09:50:59,127 [Thread-2:42680] [django.server:136] [basehttp:log_message] [WARNING]- "GET /images/a3.jpg HTTP/1.1" 404 2092
2018-12-19 09:50:59,133 [Thread-2:42680] [django.template:872] [base:_resolve_lookup] [DEBUG]- Exception while resolving variable 'name' in template 'unknown'.
Traceback (most recent call last):
  File "D:\python_env\blog\lib\site-packages\django\core\handlers\exception.py", line 34, in inner
    response = get_response(request)
  File "D:\python_env\blog\lib\site-packages\django\core\handlers\base.py", line 111, in _get_response
    resolver_match = resolver.resolve(request.path_info)
  File "D:\python_env\blog\lib\site-packages\django\urls\resolvers.py", line 520, in resolve
    raise Resolver404({'tried': tried, 'path': new_path})
django.urls.exceptions.Resolver404: {'tried': [[<URLResolver <URLPattern list> (admin:admin) 'admin/'>], [<URLPattern '^$' [name='index']>]], 'path': 'images/a4.jpg'}

During handling of the above exception, another exception occurred:

Traceback (most recent call last):
  File "D:\python_env\blog\lib\site-packages\django\template\base.py", line 829, in _resolve_lookup
    current = current[bit]
TypeError: 'URLResolver' object is not subscriptable

During handling of the above exception, another exception occurred:

Traceback (most recent call last):
  File "D:\python_env\blog\lib\site-packages\django\template\base.py", line 837, in _resolve_lookup
    current = getattr(current, bit)
AttributeError: 'URLResolver' object has no attribute 'name'

During handling of the above exception, another exception occurred:

Traceback (most recent call last):
  File "D:\python_env\blog\lib\site-packages\django\template\base.py", line 843, in _resolve_lookup
    current = current[int(bit)]
ValueError: invalid literal for int() with base 10: 'name'

During handling of the above exception, another exception occurred:

Traceback (most recent call last):
  File "D:\python_env\blog\lib\site-packages\django\template\base.py", line 850, in _resolve_lookup
    (bit, current))  # missing attribute
django.template.base.VariableDoesNotExist: Failed lookup for key [name] in <URLResolver <URLPattern list> (admin:admin) 'admin/'>
2018-12-19 09:50:59,135 [Thread-2:42680] [django.server:136] [basehttp:log_message] [WARNING]- "GET /images/a4.jpg HTTP/1.1" 404 2092
2018-12-19 09:51:32,449 [Dummy-1:47624] [django.db.backends:111] [utils:execute] [DEBUG]- (0.000) 
            SELECT name, type FROM sqlite_master
            WHERE type in ('table', 'view') AND NOT name='sqlite_sequence'
            ORDER BY name; args=None
